#VRML_SIM R2022b utf8

EXTERNPROTO "https://raw.githubusercontent.com/cyberbotics/webots/R2022b/projects/objects/backgrounds/protos/TexturedBackground.proto"
EXTERNPROTO "https://raw.githubusercontent.com/cyberbotics/webots/R2022b/projects/objects/backgrounds/protos/TexturedBackgroundLight.proto"
EXTERNPROTO "https://raw.githubusercontent.com/cyberbotics/webots/R2022b/projects/objects/tables/protos/Table.proto"
EXTERNPROTO "https://raw.githubusercontent.com/cyberbotics/webots/R2022b/projects/objects/factory/fire_extinguisher/protos/FireExtinguisher.proto"
EXTERNPROTO "https://raw.githubusercontent.com/cyberbotics/webots/R2022b/projects/objects/factory/containers/protos/WoodenBox.proto"
EXTERNPROTO "https://raw.githubusercontent.com/cyberbotics/webots/R2022b/projects/objects/apartment_structure/protos/Door.proto"
EXTERNPROTO "https://raw.githubusercontent.com/cyberbotics/webots/R2022b/projects/objects/apartment_structure/protos/Wall.proto"
EXTERNPROTO "https://raw.githubusercontent.com/cyberbotics/webots/R2022b/projects/objects/school_furniture/protos/Blackboard.proto"
EXTERNPROTO "https://raw.githubusercontent.com/cyberbotics/webots/R2022b/projects/objects/cabinet/protos/Cabinet.proto"
EXTERNPROTO "https://raw.githubusercontent.com/cyberbotics/webots/R2022b/projects/objects/factory/tools/protos/PaintBucket.proto"
EXTERNPROTO "https://raw.githubusercontent.com/cyberbotics/webots/R2022b/projects/appearances/protos/VarnishedPine.proto"
EXTERNPROTO "https://raw.githubusercontent.com/cyberbotics/webots/R2022b/projects/objects/tables/protos/Desk.proto"
EXTERNPROTO "https://raw.githubusercontent.com/cyberbotics/webots/R2022b/projects/objects/solids/protos/SolidPipe.proto"
EXTERNPROTO "https://raw.githubusercontent.com/cyberbotics/webots/R2022b/projects/objects/freight/protos/IntermodalOfficeContainer.proto"
EXTERNPROTO "https://raw.githubusercontent.com/cyberbotics/webots/R2022b/projects/humans/pedestrian/protos/Pedestrian.proto"
EXTERNPROTO "https://raw.githubusercontent.com/cyberbotics/webots/R2022b/projects/objects/floors/protos/RectangleArena.proto"
EXTERNPROTO "https://raw.githubusercontent.com/cyberbotics/webots/R2022b/projects/appearances/protos/Parquetry.proto"
EXTERNPROTO "https://raw.githubusercontent.com/cyberbotics/webots/R2022b/projects/objects/computers/protos/Monitor.proto"
EXTERNPROTO "https://raw.githubusercontent.com/cyberbotics/webots/R2022b/projects/objects/chairs/protos/OfficeChair.proto"
EXTERNPROTO "https://raw.githubusercontent.com/cyberbotics/webots/R2022b/projects/robots/universal_robots/protos/UR5e.proto"
EXTERNPROTO "https://raw.githubusercontent.com/cyberbotics/webots/R2022b/projects/devices/robotiq/protos/Robotiq3fGripper.proto"

WorldInfo {
  contactProperties [
    ContactProperties {
      material1 "arena"
    }
  ]
}
Viewpoint {
  orientation 0.22754485938517946 0.02274912980272699 -0.9735018305378771 3.20960104452382
  position 10.775042708915178 -0.658698430927674 6.307028003073246
}
TexturedBackground {
  texture "factory"
}
TexturedBackgroundLight {
  texture "factory"
}
Pedestrian {
  translation 6.01814 0.289776 1.27
  rotation 0 0 1 1.0472
}
Desk {
  translation 2.74452 3.11582 -0.00919824596641472
  rotation 0.9408562224294631 0.3350763464429348 0.05013392833416643 2.642042842147259e-17
  physics Physics {
  }
}
Wall {
  translation 8.84657 -12.0461 1.77636e-15
  rotation 0 0 1 1.5708
  name "wall(1)"
  size 0.2 60 2.4
}
PaintBucket {
  hidden position_0_0 -2.0179651418636366
  hidden rotation_1 0 -1 0 2.0179651418636366
  hidden position_1_0 -4.4752297173049086e-10
  translation 1.9000050043087866 -2.7899999015443107 -0.0023210640287596174
  rotation 0.016108581211657647 -0.9998702481839005 -2.0199325538916503e-05 0.0038280709687761086
}
Cabinet {
  hidden position_6_0 4.5261555956896815e-14
  hidden position_10_0 -2.7954141712940464e-14
  translation -5.27367 4.11358 0
}
Cabinet {
  hidden position_6_0 4.5261176847775976e-14
  hidden position_10_0 -2.7961445919696468e-14
  translation -5.27367 3.17358 0
  name "cabinet(1)"
}
Blackboard {
  translation -5.4452 -3.3242 1.67
}
Wall {
  translation -5.66824 -5.59486 1.77636e-15
  size 0.2 60 2.4
}
SolidPipe {
  translation 0.05881421943755103 2.465106730971906 0.8900035726578451
  rotation 0.716192845878128 0.6979024320342503 5.360659100318139e-05 0.00030957857415608864
  height 0.3
  radius 0.04
  physics Physics {
  }
}
WoodenBox {
  translation 2.96521 -3.28714 0.3
}
WoodenBox {
  translation 2.35329 -3.28656 0.3
  name "wooden box(1)"
}
WoodenBox {
  translation 2.35329 -3.28656 0.9
  name "wooden box(2)"
}
WoodenBox {
  translation 2.97329 -3.28656 0.9
  name "wooden box(3)"
}
FireExtinguisher {
  translation -5.123450002163994 -5.143850015014755 -0.004708884595521823
  rotation 0.9897806631475681 -0.14259817270624536 -1.0054454122507716e-09 0.007874813560367394
}
Table {
  translation 2.05155 1.88815 0
  rotation 0 0 1 1.57
}
Table {
  translation -4.04852 -0.68386 0
  name "table(1)"
}
Table {
  translation -4.06682 1.14437 -1.33227e-15
  name "table(3)"
}
Table {
  translation -0.168007 3.29728 0
  name "table(2)"
  trayAppearance VarnishedPine {
    textureTransform TextureTransform {
      scale 10 10
    }
    IBLStrength 10
  }
}
Table {
  translation 0.240864 1.893 0
  rotation 0 0 1 1.57
  name "table(4)"
  trayAppearance VarnishedPine {
    textureTransform TextureTransform {
      scale 10 10
    }
    IBLStrength 10
  }
}
Door {
  hidden translation_5 0.0010000002705243816 8.485923075340907e-11 0
  translation -5.6651 -6.60923 2.66454e-15
  position -5.695249894000207e-10
}
IntermodalOfficeContainer {
  translation 0.697281 -10.2307 2.84217e-14
}
RectangleArena {
  translation 2.01068 -5.12401 -3.55271e-14
  floorSize 60 60
  floorAppearance Parquetry {
    type "dark strip"
  }
}
OfficeChair {
  hidden position_0_0 -2.5126247706434843e-06
  hidden rotation_1 0 0 -1 2.5126026759576054e-06
  translation -3.129530000485496 1.0801400000172214 -0.00012887539424452643
  rotation 6.323281215135334e-05 -4.4976383528769094e-07 0.9999999980007046 3.141590000023536
}
OfficeChair {
  hidden position_0_0 5.3035377381483235e-06
  hidden rotation_1 0 0 1 5.3035575205233465e-06
  translation 0.5298399380018632 3.1856699163983624 4.385050215885422e-05
  rotation 0.001053997030215595 1.19972971411211e-06 0.9999994445442563 3.141590036321546
  name "office chair(1)"
}
Monitor {
  translation -4.46017 1.05845 0.76
}
Monitor {
  translation -4.46017 1.70845 0.76
  rotation 1 0 0 4.692820414042842e-06
  name "monitor(1)"
}
Robot {
  translation -3.566586299895218 -1.9154044803538086 0.08483210892122187
  rotation 0.018572057332894645 -0.0011936349885243154 0.999826811963921 1.574832886083107
  children [
    UR5e {
      hidden position_0_0 0.9999993944062393
      hidden rotation_1 0 0 1 0.9999993944062392
      hidden position_1_0 -1.5707674386031076
      hidden linearVelocity_1 0.0028438512954753665 -0.020903744978001577 0.011511950681279495
      hidden angularVelocity_1 0.03141499378771028 0.016124400443366806 -0.0008777333796740984
      hidden rotation_2 0 1 0 2.8561386497471753e-05
      hidden position_2_0 1.5708249847536533
      hidden linearVelocity_2 0.006102372705091277 -0.02729750273875636 0.008423907870750046
      hidden angularVelocity_2 0.03138187456036029 0.01613407596457363 -0.0008935704407711581
      hidden rotation_3 0 1 0 1.5708249847536533
      hidden position_3_0 -3.1415885241562034
      hidden linearVelocity_3 0.009774871280301597 -0.034002619541147146 0.015140332378096226
      hidden angularVelocity_3 0.031380095216431494 0.016137138831444846 -0.0009137380675054783
      hidden rotation_4 0 -0.9999999999999999 0 1.5707925241562033
      hidden position_4_0 -1.570796399654455
      hidden linearVelocity_4 0.009878320708923015 -0.03387393092937666 0.0202506488996039
      hidden angularVelocity_4 0.031377474626066854 0.016138083068824808 -0.0009186228599939257
      hidden rotation_5 0 0 -1 1.5707963996544547
      hidden position_5_0 3.141592813132056
      hidden linearVelocity_5 0.011491305533197554 -0.036983486367264784 0.020163391928806437
      hidden angularVelocity_5 0.03137447076955039 0.01613819359538179 -0.0009208162660545765
      hidden rotation_6 0 1 0 3.141592813132056
      hidden linearVelocity_6 0.01160032155224313 -0.036963844609605744 0.023864611428700427
      hidden angularVelocity_6 0.03137429596021553 0.016138159741110696 -0.0009234135713505807
      hidden position_7_0 -6.333279702770018e-06
      hidden position_7_1 -6.2342731960184225e-06
      hidden position_7_2 1.0000000021658346
      hidden rotation_8 0.7068252250790972 0.7073882252280593 7.617395756831882e-07 3.1415935199134184
      hidden position_8_0 1.0000037854749548
      hidden linearVelocity_8 0.011136368586284404 -0.03586850733499424 0.02593814277521559
      hidden angularVelocity_8 0.03140839266079073 0.01619109620762617 -0.0009240058669010299
      hidden rotation_9 0 0 1 0.9505037854749566
      hidden position_9_0 -3.1349004962580907e-08
      hidden linearVelocity_9 0.011194501935782638 -0.035870530136810214 0.026567422077233362
      hidden angularVelocity_9 0.031408527095248044 0.016190759750696067 -0.0009244030123860239
      hidden rotation_10 0 0 -1 0.5200000313490051
      hidden position_10_0 -0.05229999999821876
      hidden linearVelocity_10 0.011219091687074597 -0.0358510860033813 0.027716334438287048
      hidden angularVelocity_10 0.031408521257037025 0.016190764955429635 -0.0009247314492091523
      hidden linearVelocity_11 0.011236237374938837 -0.035838706719059324 0.028509014565962405
      hidden angularVelocity_11 0.031408521220015403 0.016190764966086072 -0.0009247314357387299
      hidden rotation_12 0.7068252250788408 0.7073882252282767 7.967297309875785e-07 3.1415935899494416
      hidden position_12_0 1.0000038154316557
      hidden linearVelocity_12 0.012299381924790527 -0.03812794346163098 0.02587362702931485
      hidden angularVelocity_12 0.03140850501272646 0.016191315994424624 -0.0009240723228924947
      hidden rotation_13 0 0 1 0.9505038154316579
      hidden position_13_0 -3.1352693764493234e-08
      hidden linearVelocity_13 0.012360170338851544 -0.03813009610989075 0.02650155273665682
      hidden angularVelocity_13 0.03140862513206716 0.016190998892810428 -0.000924495539734191
      hidden rotation_14 0 0 -1 0.520000031352694
      hidden position_14_0 -0.0522999999982196
      hidden linearVelocity_14 0.012384766296217636 -0.038110560307965634 0.027650480754612693
      hidden angularVelocity_14 0.03140861927635595 0.016191004113299275 -0.0009248248655214709
      hidden linearVelocity_15 0.01240191384140566 -0.03809815559705257 0.028443170905700678
      hidden angularVelocity_15 0.03140861923933447 0.016191004123950407 -0.0009248248523252836
      hidden rotation_16 0 0 1 0.950500002165837
      hidden position_16_0 -3.134585334397188e-08
      hidden linearVelocity_16 0.011613207108181874 -0.036927961043230206 0.02487709248055743
      hidden angularVelocity_16 0.03137429064467072 0.016138158257309843 -0.000923467458026961
      hidden rotation_17 0 0 -1 0.5200000313458534
      hidden position_17_0 -0.05229999999725059
      hidden linearVelocity_17 0.011681085855653427 -0.03694366518280304 0.02689015653264943
      hidden angularVelocity_17 0.03137429483334936 0.01613815204182161 -0.0009231608800981536
      hidden linearVelocity_18 0.011727079866058818 -0.03695475789387999 0.028258929090317568
      hidden angularVelocity_18 0.03137429477736491 0.016138152043045383 -0.0009231608927263916
      translation 0.25 0 0.4
      controller "ur5_webot_ctrl"
      toolSlot [
        Robotiq3fGripper {
        }
      ]
      staticBase FALSE
    }
    Shape {
      appearance PBRAppearance {
        baseColor 0 0 0
        roughness 0.5
        metalness 0.2
      }
      geometry Mesh {
        url [
          "https://raw.githubusercontent.com/cyberbotics/webots/R2022b/projects/robots/robotnik/summit_xl_steel/protos/meshes/summit_xls_chassis.dae"
        ]
      }
    }
    Solid {
      translation 0 0 0.39062
      children [
        Shape {
          appearance DEF DARKGREY PBRAppearance {
            baseColor 0.5 0.5 0.5
            metalness 0.9
          }
          geometry Mesh {
            url [
              "https://raw.githubusercontent.com/cyberbotics/webots/R2022b/projects/robots/robotnik/summit_xl_steel/protos/meshes/summit_xls_chapas_inox_tapas.stl"
            ]
          }
        }
      ]
      name "base_chapa"
    }
    Solid {
      translation 0.359 0 0.30062
      children [
        Shape {
          appearance USE DARKGREY
          geometry Mesh {
            url [
              "https://raw.githubusercontent.com/cyberbotics/webots/R2022b/projects/robots/robotnik/summit_xl_steel/protos/meshes/summit_xls_chapas_inox_tapas_front.stl"
            ]
          }
        }
      ]
      name "base_chapa_front"
    }
    Solid {
      translation 0 0.28931 0.29062
      children [
        DEF LOGO Shape {
          appearance USE DARKGREY
          geometry Mesh {
            url [
              "https://raw.githubusercontent.com/cyberbotics/webots/R2022b/projects/robots/robotnik/summit_xl_steel/protos/meshes/robotnik_logo_chasis.stl"
            ]
          }
        }
      ]
      name "base_logo_left"
    }
    Solid {
      translation 0 -0.28931 0.29062
      rotation 0 0 1 3.141593
      children [
        USE LOGO
      ]
      name "base_logo_right"
    }
    Solid {
      translation 0.345 0 0
      rotation 0 0 -1 1.570796
      children [
        USE LOGO
      ]
      name "base_logo_front"
    }
    Solid {
      translation -0.345 0 0
      rotation 0 0 1 1.570796
      children [
        USE LOGO
      ]
      name "base_logo_rear"
    }
    HingeJoint {
      jointParameters HingeJointParameters {
        position -213.42139530455157
        axis 0 1 0
        anchor 0.2225 -0.2045 0
      }
      device [
        RotationalMotor {
          name "front_right_wheel_joint"
          maxVelocity 100
          maxTorque 100
        }
        PositionSensor {
          name "front_right_wheel_joint_sensor"
        }
      ]
      endPoint Solid {
        translation 0.2231536704255716 -0.20449996661010172 0.0031180685614655475
        rotation 0.9893919925298739 0.10272148655548277 -0.1027218638732644 1.5814644711185109
        children [
          DEF INTERIOR_WHEEL Group {
            children [
              Shape {
                appearance DEF WHEEL_APPEARANCE PBRAppearance {
                  baseColor 0.381347 0.381347 0.381347
                  metalness 0.4
                  emissiveColor 0.202 0.202 0.202
                }
                geometry Mesh {
                  url [
                    "https://raw.githubusercontent.com/cyberbotics/webots/R2022b/projects/robots/robotnik/summit_xl_steel/protos/meshes/omni_wheel_rims_int.dae"
                  ]
                }
              }
              Shape {
                appearance DEF ROLLERS_APPEARANCE PBRAppearance {
                  baseColor 0.08132 0.08132 0.08132
                  roughness 0.8
                  metalness 0
                }
                geometry Mesh {
                  url [
                    "https://raw.githubusercontent.com/cyberbotics/webots/R2022b/projects/robots/robotnik/summit_xl_steel/protos/meshes/omni_wheel_rollers_int.dae"
                  ]
                }
              }
            ]
          }
        ]
        name "front_right_wheel_link"
        contactMaterial "InteriorWheelMat"
        boundingObject DEF WHEEL_BO Cylinder {
          height 0.08
          radius 0.123
        }
        physics Physics {
          density -1
          mass 6.5
          centerOfMass [
            0 0 0
          ]
          inertiaMatrix [
            0.0303095 0.05241925 0.0303095
            0 0 0
          ]
        }
        linearVelocity -0.00563464158015087 -0.003551446375047062 0.007184423983787561
        angularVelocity 0.031369651251529296 0.016035733532708457 -0.0008610146672377579
      }
    }
    HingeJoint {
      jointParameters HingeJointParameters {
        position 935.5012131830059
        axis 0 1 0
        anchor 0.2225 0.2045 0
      }
      device [
        RotationalMotor {
          name "front_left_wheel_joint"
          maxVelocity 100
          maxTorque 100
        }
        PositionSensor {
          name "front_left_wheel_joint_sensor"
        }
      ]
      endPoint Solid {
        translation 0.22046422493430662 0.20450003337390876 0.0024483139252284014
        rotation -0.8904953498843261 0.3217275799606716 -0.3217287617342306 4.596667059974239
        children [
          DEF EXTERIOR_WHEEL Group {
            children [
              Shape {
                appearance USE WHEEL_APPEARANCE
                geometry Mesh {
                  url [
                    "https://raw.githubusercontent.com/cyberbotics/webots/R2022b/projects/robots/robotnik/summit_xl_steel/protos/meshes/omni_wheel_rims_ext.dae"
                  ]
                }
              }
              Shape {
                appearance USE ROLLERS_APPEARANCE
                geometry Mesh {
                  url [
                    "https://raw.githubusercontent.com/cyberbotics/webots/R2022b/projects/robots/robotnik/summit_xl_steel/protos/meshes/omni_wheel_rollers_ext.dae"
                  ]
                }
              }
            ]
          }
        ]
        name "front_left_wheel_link"
        contactMaterial "ExteriorWheelMat"
        boundingObject USE WHEEL_BO
        physics Physics {
          density -1
          mass 6.5
          centerOfMass [
            0 0 0
          ]
          inertiaMatrix [
            0.0303095 0.05241925 0.0303095
            0 0 0
          ]
        }
        linearVelocity -0.007694583675311076 -0.061207801678259496 -0.047380765135430505
        angularVelocity -24.354478779053917 -0.08177367633192686 0.4125046294545892
      }
    }
    HingeJoint {
      jointParameters HingeJointParameters {
        position -216.43463391838804
        axis 0 1 0
        anchor -0.2225 0.2045 0
      }
      device [
        RotationalMotor {
          name "back_left_wheel_joint"
          maxVelocity 100
          maxTorque 100
        }
        PositionSensor {
          name "back_left_wheel_joint_sensor"
        }
      ]
      endPoint Solid {
        translation -0.22353164393143943 0.2045000329443426 -0.0029634584160656875
        rotation 0.11880761702299936 -0.7020972613464679 0.7020998402984479 2.9050869055932043
        children [
          USE INTERIOR_WHEEL
        ]
        name "back_left_wheel_link"
        contactMaterial "InteriorWheelMat"
        boundingObject USE WHEEL_BO
        physics Physics {
          density -1
          mass 6.5
          centerOfMass [
            0 0 0
          ]
          inertiaMatrix [
            0.0303095 0.05241925 0.0303095
            0 0 0
          ]
        }
        linearVelocity -0.006274867385254576 -0.0027741264190263063 3.6654638821513597e-06
        angularVelocity 0.031194571391932192 0.016052434006364937 -0.0008606879400517289
      }
    }
    HingeJoint {
      jointParameters HingeJointParameters {
        position 997.5009240305113
        axis 0 1 0
        anchor -0.2225 -0.2045 0
      }
      device [
        RotationalMotor {
          name "back_right_wheel_joint"
          maxVelocity 100
          maxTorque 100
        }
        PositionSensor {
          name "back_right_wheel_joint_sensor"
        }
      ]
      endPoint Solid {
        translation -0.22563644464719906 -0.20449996703966933 0.00014122842442899122
        rotation -0.594768173541973 0.5684401665653723 -0.5684422545665279 4.214716802535297
        children [
          USE EXTERIOR_WHEEL
        ]
        name "back_right_wheel_link"
        contactMaterial "ExteriorWheelMat"
        boundingObject USE WHEEL_BO
        physics Physics {
          density -1
          mass 6.5
          centerOfMass [
            0 0 0
          ]
          inertiaMatrix [
            0.0303095 0.05241925 0.0303095
            0 0 0
          ]
        }
        linearVelocity -0.007343788826264958 -0.0849873196290066 -0.024415770778645297
        angularVelocity -24.354391483474 -0.0816720721480284 0.41253547964518794
      }
    }
    Solid {
      translation 0.35 0 0.09
      name "base_docking_contact"
    }
    DEF IMU Transform {
      translation 0.127 -0.129 0.212
      children [
        Shape {
          appearance PBRAppearance {
            baseColor 0.5 0.5 0.5
            roughness 1
            metalness 0
          }
          geometry Box {
            size 0.001 0.001 0.001
          }
        }
        Accelerometer {
        }
        Gyro {
        }
        Compass {
        }
      ]
    }
    DEF RGBD Solid {
      translation 0.3585 0 0.29062
      children [
        Solid {
          translation 0.007 0 0
          children [
            Shape {
              appearance PBRAppearance {
                baseColor 0.3 0.3 0.3
                roughness 1
                roughnessMap ImageTexture {
                  url [
                    "https://raw.githubusercontent.com/cyberbotics/webots/R2022b/projects/appearances/protos/textures/plastic/plastic_rough_roughness.jpg"
                  ]
                }
                metalness 0
                normalMap ImageTexture {
                  url [
                    "https://raw.githubusercontent.com/cyberbotics/webots/R2022b/projects/appearances/protos/textures/plastic/plastic_rough_normal.jpg"
                  ]
                }
              }
              geometry Mesh {
                url [
                  "https://raw.githubusercontent.com/cyberbotics/webots/R2022b/projects/robots/robotnik/summit_xl_steel/protos/meshes/orbbec_astra.dae"
                ]
              }
            }
            Shape {
              appearance PBRAppearance {
                baseColor 0 0 0
                roughness 1
                roughnessMap ImageTexture {
                  url [
                    "https://raw.githubusercontent.com/cyberbotics/webots/R2022b/projects/appearances/protos/textures/plastic/plastic_rough_roughness.jpg"
                  ]
                }
                metalness 0
                normalMap ImageTexture {
                  url [
                    "https://raw.githubusercontent.com/cyberbotics/webots/R2022b/projects/appearances/protos/textures/plastic/plastic_rough_normal.jpg"
                  ]
                }
              }
              geometry Mesh {
                url [
                  "https://raw.githubusercontent.com/cyberbotics/webots/R2022b/projects/robots/robotnik/summit_xl_steel/protos/meshes/orbbec_astra_cover.dae"
                ]
              }
            }
          ]
          name "front_rgbd_camera_link"
          boundingObject Transform {
            translation -0.02 0 0.015
            children [
              Box {
                size 0.04 0.165 0.03
              }
            ]
          }
        }
        Camera {
          translation 0 0 0.015
          name "rgb_camera"
          fieldOfView 1.0472
          width 1280
          height 720
        }
        RangeFinder {
          translation 0 0 0.015
          name "depth_camera"
          fieldOfView 1.0472
          width 640
          height 480
          minRange 0.6
          maxRange 8
        }
      ]
    }
    GPS {
      translation -0.365 -0.167 0.302
    }
    Transform {
      translation 0 0 0.39062
    }
    Transform {
      translation 0.2865 -0.20894 0.193
      rotation 0.9238766724085287 -0.3826903371909772 0 3.14159
    }
    Transform {
      translation -0.2865 0.20894 0.193
      rotation 0.3826903371909772 0.9238766724085287 0 3.14159
    }
  ]
  name "Summit-XL Steel"
  boundingObject Group {
    children [
      Transform {
        translation 0 0 0.3
        children [
          Box {
            size 0.719 0.57861 0.18
          }
        ]
      }
      Transform {
        translation 0 0 0.176
        children [
          Box {
            size 0.524 0.27 0.06495
          }
        ]
      }
      Transform {
        translation 0 0 0.046225
        children [
          Box {
            size 0.69 0.27 0.1945
          }
        ]
      }
    ]
  }
  physics Physics {
    density -1
    mass 125
    centerOfMass [
      0 0 0
    ]
    inertiaMatrix [
      1.391 6.853 6.125
      0.004 0 0
    ]
  }
  controller "keyboard_control"
  controllerArgs [
    ""
  ]
  linearVelocity -0.006361506032764311 -0.0034745855421784173 0.0038908725757964913
  angularVelocity 0.03145451999763778 0.016121204460975862 -0.0008594953473241632
}
